<?xml version="1.0"?>
<robot xmlns:xacro="http://wiki.ros.org/xacro">
    <!-- 
        Author: Adarsh Karan K P
    -->
    
    <xacro:include filename="$(find elite_description)/urdf/macro/elite_common.xacro" />

    <xacro:macro name="elite_robot" params="
    name
    tf_prefix
    parent
    *origin
    joint_limits_parameters_file
    kinematics_parameters_file
    physical_parameters_file"
    >

    <!-- Load parameters -->
    <xacro:read_model_data
        joint_limits_parameters_file="${joint_limits_parameters_file}"
        kinematics_parameters_file="${kinematics_parameters_file}"
        physical_parameters_file="${physical_parameters_file}"
    />
    <!-- World Link and Joint- needed when launching only the arm -->
    <xacro:if value="${parent == 'world'}">
        <link name="${tf_prefix}world" />
    </xacro:if>

    <joint name="${tf_prefix}${parent}_joint" type="fixed">
    <xacro:insert_block name="origin" />
    <parent link="${parent}" />               
    <child link="${tf_prefix}base_link" />
    </joint>

    <!-- Base Link -->
    <link name="${tf_prefix}base_link">
        <inertial>
        <origin xyz="${base_link_origin}" rpy="0 0 0"/>
        <mass value="${base_link_mass}"/>
        <inertia ixx="${base_link_ixx}" ixy="${base_link_ixy}" ixz="${base_link_ixz}"
                    iyy="${base_link_iyy}" iyz="${base_link_iyz}" izz="${base_link_izz}"/>
        </inertial>
        <visual>
        <geometry>
            <mesh filename="package://elite_description/meshes/ec66/base_link.stl"/>
        </geometry>
        <material name="">
            <color rgba="1 1 1 1" />
        </material>
        </visual>
        <collision>
        <geometry>
            <mesh filename="package://elite_description/meshes/ec66/base_link.stl"/>
        </geometry>
        </collision>
    </link>

    <!-- link1 and joint1 -->
    <link name="${tf_prefix}link1">
        <inertial>
            <origin xyz="${link1_origin}" rpy="0 0 0"/>
            <mass value="${link1_mass}" />
            <inertia 
                ixx="${link1_ixx}" 
                ixy="${link1_ixy}" 
                ixz="${link1_ixz}" 
                iyy="${link1_iyy}" 
                iyz="${link1_iyz}" 
                izz="${link1_izz}" />
        </inertial>
        <visual>
            <geometry>
                <mesh filename="package://elite_description/meshes/ec66/link1.stl"/>
            </geometry>
            <material name="">
                <color rgba="1 1 1 1" />
            </material>
        </visual>
        <collision>
            <geometry>
                <mesh filename="package://elite_description/meshes/ec66/link1.stl"/>
            </geometry>
        </collision>
    </link>
    <joint name="${tf_prefix}joint1" type="revolute">
        <origin xyz="${joint1_xyz}" rpy="${joint1_rpy}" />
        <parent link="${tf_prefix}base_link" />
        <child link="${tf_prefix}link1" />
        <axis xyz="0 0 1" />
        <limit 
            lower="${joint1_lower}"
            upper="${joint1_upper}"
            effort="${joint1_effort}"
            velocity="${joint1_velocity}" 
        />
        <dynamics damping="${joint_dynamics_joint1_damping}"
                    friction="${joint_dynamics_joint1_friction}"/>
    </joint>

    <!-- link2 and joint2 -->
    <link name="${tf_prefix}link2">
        <inertial>
            <origin xyz="${link2_origin}" rpy="0 0 0"/>
            <mass value="${link2_mass}" />
            <inertia 
                ixx="${link2_ixx}" 
                ixy="${link2_ixy}" 
                ixz="${link2_ixz}" 
                iyy="${link2_iyy}" 
                iyz="${link2_iyz}" 
                izz="${link2_izz}" />
        </inertial>
        <visual>
            <geometry>
                <mesh filename="package://elite_description/meshes/ec66/link2.stl"/>
            </geometry>
            <material name="">
                <color rgba="1 1 1 1" />
            </material>
        </visual>
        <collision>
            <geometry>
                <mesh filename="package://elite_description/meshes/ec66/link2.stl"/>
            </geometry>
        </collision>
    </link>
    <joint name="${tf_prefix}joint2" type="revolute">
        <origin xyz="${joint2_xyz}" rpy="${joint2_rpy}" />
        <parent link="${tf_prefix}link1" />
        <child link="${tf_prefix}link2" />
        <axis xyz="0 0 1" />
        <limit 
            lower="${joint2_lower}"
            upper="${joint2_upper}"
            effort="${joint2_effort}"
            velocity="${joint2_velocity}" 
        />
        <dynamics damping="${joint_dynamics_joint2_damping}"
                    friction="${joint_dynamics_joint2_friction}"/>
    </joint>

    <!-- link3 and joint3 -->
    <link name="${tf_prefix}link3">
        <inertial>
            <origin xyz="${link3_origin}" rpy="0 0 0"/>
            <mass value="${link3_mass}" />
            <inertia 
                ixx="${link3_ixx}" 
                ixy="${link3_ixy}" 
                ixz="${link3_ixz}" 
                iyy="${link3_iyy}" 
                iyz="${link3_iyz}" 
                izz="${link3_izz}" />
        </inertial>
        <visual>
            <geometry>
                <mesh filename="package://elite_description/meshes/ec66/link3.stl"/>
            </geometry>
            <material name="">
                <color rgba="1 1 1 1" />
            </material>
        </visual>
        <collision>
            <geometry>
                <mesh filename="package://elite_description/meshes/ec66/link3.stl"/>
            </geometry>
        </collision>
    </link>
    <joint name="${tf_prefix}joint3" type="revolute">
        <origin xyz="${joint3_xyz}" rpy="${joint3_rpy}" />
        <parent link="${tf_prefix}link2" />
        <child link="${tf_prefix}link3" />
        <axis xyz="0 0 1" />
        <limit 
            lower="${joint3_lower}"
            upper="${joint3_upper}"
            effort="${joint3_effort}"
            velocity="${joint3_velocity}" 
        />
        <dynamics damping="${joint_dynamics_joint3_damping}"
                    friction="${joint_dynamics_joint3_friction}"/>
    </joint>

    <!-- link4 and joint4 -->
    <link name="${tf_prefix}link4">
        <inertial>
            <origin xyz="${link4_origin}" rpy="0 0 0"/>
            <mass value="${link4_mass}" />
            <inertia 
                ixx="${link4_ixx}" 
                ixy="${link4_ixy}" 
                ixz="${link4_ixz}" 
                iyy="${link4_iyy}" 
                iyz="${link4_iyz}" 
                izz="${link4_izz}" />
        </inertial>
        <visual>
            <geometry>
                <mesh filename="package://elite_description/meshes/ec66/link4.stl"/>
            </geometry>
            <material name="">
                <color rgba="1 1 1 1" />
            </material>
        </visual>
        <collision>
            <geometry>
                <mesh filename="package://elite_description/meshes/ec66/link4.stl"/>
            </geometry>
        </collision>
    </link>
    <joint name="${tf_prefix}joint4" type="revolute">
        <origin xyz="${joint4_xyz}" rpy="${joint4_rpy}" />
        <parent link="${tf_prefix}link3" />
        <child link="${tf_prefix}link4" />
        <axis xyz="0 0 1" />
        <limit 
            lower="${joint4_lower}"
            upper="${joint4_upper}"
            effort="${joint4_effort}"
            velocity="${joint4_velocity}" 
        />
        <dynamics damping="${joint_dynamics_joint4_damping}"
                    friction="${joint_dynamics_joint4_friction}"/>
    </joint>

    <!-- link5 and joint5 -->
    <link name="${tf_prefix}link5">
        <inertial>
            <origin xyz="${link5_origin}" rpy="0 0 0"/>
            <mass value="${link5_mass}" />
            <inertia 
                ixx="${link5_ixx}" 
                ixy="${link5_ixy}" 
                ixz="${link5_ixz}" 
                iyy="${link5_iyy}" 
                iyz="${link5_iyz}" 
                izz="${link5_izz}" />
        </inertial>
        <visual>
            <geometry>
                <mesh filename="package://elite_description/meshes/ec66/link5.stl"/>
            </geometry>
            <material name="">
                <color rgba="1 1 1 1" />
            </material>
        </visual>
        <collision>
            <geometry>
                <mesh filename="package://elite_description/meshes/ec66/link5.stl"/>
            </geometry>
        </collision>
    </link>
    <joint name="${tf_prefix}joint5" type="revolute">
        <origin xyz="${joint5_xyz}" rpy="${joint5_rpy}" />
        <parent link="${tf_prefix}link4" />
        <child link="${tf_prefix}link5" />
        <axis xyz="0 0 1" />
        <limit 
            lower="${joint5_lower}"
            upper="${joint5_upper}"
            effort="${joint5_effort}"
            velocity="${joint5_velocity}" 
        />
        <dynamics damping="${joint_dynamics_joint5_damping}"
                    friction="${joint_dynamics_joint5_friction}"/>
    </joint>

    <!-- link6 and joint6 -->
    <link name="${tf_prefix}link6">
        <inertial>
            <origin xyz="${link6_origin}" rpy="0 0 0"/>
            <mass value="${link6_mass}" />
            <inertia 
                ixx="${link6_ixx}" 
                ixy="${link6_ixy}" 
                ixz="${link6_ixz}" 
                iyy="${link6_iyy}" 
                iyz="${link6_iyz}" 
                izz="${link6_izz}" />
        </inertial>
        <visual>
            <geometry>
                <mesh filename="package://elite_description/meshes/ec66/link6.stl"/>
            </geometry>
            <material name="">
                <color rgba="1 1 1 1" />
            </material>
        </visual>
        <collision>
            <geometry>
                <mesh filename="package://elite_description/meshes/ec66/link6.stl"/>
            </geometry>
        </collision>
    </link>
    <joint name="${tf_prefix}joint6" type="revolute">
        <origin xyz="${joint6_xyz}" rpy="${joint6_rpy}" />
        <parent link="${tf_prefix}link5" />
        <child link="${tf_prefix}link6" />
        <axis xyz="0 0 1" />
        <limit 
            lower="${joint6_lower}"
            upper="${joint6_upper}"
            effort="${joint6_effort}"
            velocity="${joint6_velocity}" 
        />
        <dynamics damping="${joint_dynamics_joint6_damping}"
                    friction="${joint_dynamics_joint6_friction}"/>
    </joint>

    <!-- flange -->
    <link name="${tf_prefix}flange" />
    <joint name="${tf_prefix}flange_joint" type="fixed">
        <origin xyz="0 0 0" rpy="0 0 0" />
        <parent link="${tf_prefix}link6" />
        <child link="${tf_prefix}flange" />
    </joint>

    </xacro:macro>

</robot>
